[2024-11-30T18:34:59.835+0000] {task_context_logger.py:104} WARNING - Marking task instance <TaskInstance: stockprices_v2_decorator.return_last_90d_price scheduled__2024-11-30T11:20:00+00:00 [queued]> stuck in queued as failed. If the task instance has available retries, it will be retried.
[2024-11-30T18:35:02.105+0000] {task_context_logger.py:104} ERROR - Executor reports task instance <TaskInstance: stockprices_v2_decorator.return_last_90d_price scheduled__2024-11-30T11:20:00+00:00 [queued]> finished (failed) although the task says it's queued. (Info: None) Was the task killed externally?
