[2024-11-30T07:36:42.459+0000] {local_task_job_runner.py:120} INFO - ::group::Pre task execution logs
[2024-11-30T07:36:42.535+0000] {taskinstance.py:2076} INFO - Dependencies all met for dep_context=non-requeueable deps ti=<TaskInstance: stockprices_v2_decorator.extract__1 scheduled__2024-11-30T07:20:00+00:00 [queued]>
[2024-11-30T07:36:42.573+0000] {taskinstance.py:2076} INFO - Dependencies all met for dep_context=requeueable deps ti=<TaskInstance: stockprices_v2_decorator.extract__1 scheduled__2024-11-30T07:20:00+00:00 [queued]>
[2024-11-30T07:36:42.575+0000] {taskinstance.py:2306} INFO - Starting attempt 1 of 2
[2024-11-30T07:36:42.614+0000] {taskinstance.py:2330} INFO - Executing <Task(_PythonDecoratedOperator): extract__1> on 2024-11-30 07:20:00+00:00
[2024-11-30T07:36:42.633+0000] {warnings.py:110} WARNING - /home/***/.local/lib/python3.12/site-packages/***/task/task_runner/standard_task_runner.py:61: DeprecationWarning: This process (pid=1507) is multi-threaded, use of fork() may lead to deadlocks in the child.
  pid = os.fork()

[2024-11-30T07:36:42.637+0000] {standard_task_runner.py:63} INFO - Started process 1520 to run task
[2024-11-30T07:36:42.660+0000] {standard_task_runner.py:90} INFO - Running: ['***', 'tasks', 'run', 'stockprices_v2_decorator', 'extract__1', 'scheduled__2024-11-30T07:20:00+00:00', '--job-id', '2864', '--raw', '--subdir', 'DAGS_FOLDER/stockprices_v2_decorator(3).py', '--cfg-path', '/tmp/tmp1dha9991']
[2024-11-30T07:36:42.664+0000] {standard_task_runner.py:91} INFO - Job 2864: Subtask extract__1
[2024-11-30T07:36:42.810+0000] {task_command.py:426} INFO - Running <TaskInstance: stockprices_v2_decorator.extract__1 scheduled__2024-11-30T07:20:00+00:00 [running]> on host 3627cdc70e56
[2024-11-30T07:36:43.001+0000] {taskinstance.py:2648} INFO - Exporting env vars: AIRFLOW_CTX_DAG_OWNER='***' AIRFLOW_CTX_DAG_ID='stockprices_v2_decorator' AIRFLOW_CTX_TASK_ID='extract__1' AIRFLOW_CTX_EXECUTION_DATE='2024-11-30T07:20:00+00:00' AIRFLOW_CTX_TRY_NUMBER='1' AIRFLOW_CTX_DAG_RUN_ID='scheduled__2024-11-30T07:20:00+00:00'
[2024-11-30T07:36:43.005+0000] {taskinstance.py:430} INFO - ::endgroup::
[2024-11-30T07:36:43.111+0000] {taskinstance.py:441} INFO - ::group::Post task execution logs
[2024-11-30T07:36:43.115+0000] {taskinstance.py:2905} ERROR - Task failed with exception
Traceback (most recent call last):
  File "/home/airflow/.local/lib/python3.12/site-packages/urllib3/connection.py", line 198, in _new_conn
    sock = connection.create_connection(
           ^^^^^^^^^^^^^^^^^^^^^^^^^^^^^
  File "/home/airflow/.local/lib/python3.12/site-packages/urllib3/util/connection.py", line 60, in create_connection
    for res in socket.getaddrinfo(host, port, family, socket.SOCK_STREAM):
               ^^^^^^^^^^^^^^^^^^^^^^^^^^^^^^^^^^^^^^^^^^^^^^^^^^^^^^^^^^
  File "/usr/local/lib/python3.12/socket.py", line 963, in getaddrinfo
    for res in _socket.getaddrinfo(host, port, family, type, proto, flags):
               ^^^^^^^^^^^^^^^^^^^^^^^^^^^^^^^^^^^^^^^^^^^^^^^^^^^^^^^^^^^
socket.gaierror: [Errno -2] Name or service not known

The above exception was the direct cause of the following exception:

Traceback (most recent call last):
  File "/home/airflow/.local/lib/python3.12/site-packages/urllib3/connectionpool.py", line 793, in urlopen
    response = self._make_request(
               ^^^^^^^^^^^^^^^^^^^
  File "/home/airflow/.local/lib/python3.12/site-packages/urllib3/connectionpool.py", line 491, in _make_request
    raise new_e
  File "/home/airflow/.local/lib/python3.12/site-packages/urllib3/connectionpool.py", line 467, in _make_request
    self._validate_conn(conn)
  File "/home/airflow/.local/lib/python3.12/site-packages/urllib3/connectionpool.py", line 1099, in _validate_conn
    conn.connect()
  File "/home/airflow/.local/lib/python3.12/site-packages/urllib3/connection.py", line 616, in connect
    self.sock = sock = self._new_conn()
                       ^^^^^^^^^^^^^^^^
  File "/home/airflow/.local/lib/python3.12/site-packages/urllib3/connection.py", line 205, in _new_conn
    raise NameResolutionError(self.host, self, e) from e
urllib3.exceptions.NameResolutionError: <urllib3.connection.HTTPSConnection object at 0xffff6bf49010>: Failed to resolve 'www.alphavantage.co' ([Errno -2] Name or service not known)

The above exception was the direct cause of the following exception:

Traceback (most recent call last):
  File "/home/airflow/.local/lib/python3.12/site-packages/requests/adapters.py", line 486, in send
    resp = conn.urlopen(
           ^^^^^^^^^^^^^
  File "/home/airflow/.local/lib/python3.12/site-packages/urllib3/connectionpool.py", line 847, in urlopen
    retries = retries.increment(
              ^^^^^^^^^^^^^^^^^^
  File "/home/airflow/.local/lib/python3.12/site-packages/urllib3/util/retry.py", line 515, in increment
    raise MaxRetryError(_pool, url, reason) from reason  # type: ignore[arg-type]
    ^^^^^^^^^^^^^^^^^^^^^^^^^^^^^^^^^^^^^^^^^^^^^^^^^^^
urllib3.exceptions.MaxRetryError: HTTPSConnectionPool(host='www.alphavantage.co', port=443): Max retries exceeded with url: /query?function=TIME_SERIES_DAILY&symbol=NVDA&apikey=*** (Caused by NameResolutionError("<urllib3.connection.HTTPSConnection object at 0xffff6bf49010>: Failed to resolve 'www.alphavantage.co' ([Errno -2] Name or service not known)"))

During handling of the above exception, another exception occurred:

Traceback (most recent call last):
  File "/home/airflow/.local/lib/python3.12/site-packages/airflow/models/taskinstance.py", line 465, in _execute_task
    result = _execute_callable(context=context, **execute_callable_kwargs)
             ^^^^^^^^^^^^^^^^^^^^^^^^^^^^^^^^^^^^^^^^^^^^^^^^^^^^^^^^^^^^^
  File "/home/airflow/.local/lib/python3.12/site-packages/airflow/models/taskinstance.py", line 432, in _execute_callable
    return execute_callable(context=context, **execute_callable_kwargs)
           ^^^^^^^^^^^^^^^^^^^^^^^^^^^^^^^^^^^^^^^^^^^^^^^^^^^^^^^^^^^^
  File "/home/airflow/.local/lib/python3.12/site-packages/airflow/models/baseoperator.py", line 400, in wrapper
    return func(self, *args, **kwargs)
           ^^^^^^^^^^^^^^^^^^^^^^^^^^^
  File "/home/airflow/.local/lib/python3.12/site-packages/airflow/decorators/base.py", line 265, in execute
    return_value = super().execute(context)
                   ^^^^^^^^^^^^^^^^^^^^^^^^
  File "/home/airflow/.local/lib/python3.12/site-packages/airflow/models/baseoperator.py", line 400, in wrapper
    return func(self, *args, **kwargs)
           ^^^^^^^^^^^^^^^^^^^^^^^^^^^
  File "/home/airflow/.local/lib/python3.12/site-packages/airflow/operators/python.py", line 235, in execute
    return_value = self.execute_callable()
                   ^^^^^^^^^^^^^^^^^^^^^^^
  File "/home/airflow/.local/lib/python3.12/site-packages/airflow/operators/python.py", line 252, in execute_callable
    return self.python_callable(*self.op_args, **self.op_kwargs)
           ^^^^^^^^^^^^^^^^^^^^^^^^^^^^^^^^^^^^^^^^^^^^^^^^^^^^^
  File "/opt/airflow/dags/stockprices_v2_decorator(3).py", line 41, in extract
    response = requests.get(url)
               ^^^^^^^^^^^^^^^^^
  File "/home/airflow/.local/lib/python3.12/site-packages/requests/api.py", line 73, in get
    return request("get", url, params=params, **kwargs)
           ^^^^^^^^^^^^^^^^^^^^^^^^^^^^^^^^^^^^^^^^^^^^
  File "/home/airflow/.local/lib/python3.12/site-packages/requests/api.py", line 59, in request
    return session.request(method=method, url=url, **kwargs)
           ^^^^^^^^^^^^^^^^^^^^^^^^^^^^^^^^^^^^^^^^^^^^^^^^^
  File "/home/airflow/.local/lib/python3.12/site-packages/requests/sessions.py", line 589, in request
    resp = self.send(prep, **send_kwargs)
           ^^^^^^^^^^^^^^^^^^^^^^^^^^^^^^
  File "/home/airflow/.local/lib/python3.12/site-packages/requests/sessions.py", line 703, in send
    r = adapter.send(request, **kwargs)
        ^^^^^^^^^^^^^^^^^^^^^^^^^^^^^^^
  File "/home/airflow/.local/lib/python3.12/site-packages/requests/adapters.py", line 519, in send
    raise ConnectionError(e, request=request)
requests.exceptions.ConnectionError: HTTPSConnectionPool(host='www.alphavantage.co', port=443): Max retries exceeded with url: /query?function=TIME_SERIES_DAILY&symbol=NVDA&apikey=*** (Caused by NameResolutionError("<urllib3.connection.HTTPSConnection object at 0xffff6bf49010>: Failed to resolve 'www.alphavantage.co' ([Errno -2] Name or service not known)"))
[2024-11-30T07:36:43.143+0000] {taskinstance.py:1206} INFO - Marking task as UP_FOR_RETRY. dag_id=stockprices_v2_decorator, task_id=extract__1, run_id=scheduled__2024-11-30T07:20:00+00:00, execution_date=20241130T072000, start_date=20241130T073642, end_date=20241130T073643
[2024-11-30T07:36:43.163+0000] {standard_task_runner.py:110} ERROR - Failed to execute job 2864 for task extract__1 (HTTPSConnectionPool(host='www.alphavantage.co', port=443): Max retries exceeded with url: /query?function=TIME_SERIES_DAILY&symbol=NVDA&apikey=*** (Caused by NameResolutionError("<urllib3.connection.HTTPSConnection object at 0xffff6bf49010>: Failed to resolve 'www.alphavantage.co' ([Errno -2] Name or service not known)")); 1520)
[2024-11-30T07:36:43.253+0000] {local_task_job_runner.py:240} INFO - Task exited with return code 1
[2024-11-30T07:36:43.270+0000] {local_task_job_runner.py:222} INFO - ::endgroup::
