[2024-12-03T07:16:02.483+0000] {local_task_job_runner.py:120} INFO - ::group::Pre task execution logs
[2024-12-03T07:16:02.509+0000] {taskinstance.py:2076} INFO - Dependencies all met for dep_context=non-requeueable deps ti=<TaskInstance: job_listings_etl_v2.extract_csv scheduled__2024-12-02T00:00:00+00:00 [queued]>
[2024-12-03T07:16:02.514+0000] {taskinstance.py:2076} INFO - Dependencies all met for dep_context=requeueable deps ti=<TaskInstance: job_listings_etl_v2.extract_csv scheduled__2024-12-02T00:00:00+00:00 [queued]>
[2024-12-03T07:16:02.515+0000] {taskinstance.py:2306} INFO - Starting attempt 4 of 4
[2024-12-03T07:16:02.525+0000] {taskinstance.py:2330} INFO - Executing <Task(_PythonDecoratedOperator): extract_csv> on 2024-12-02 00:00:00+00:00
[2024-12-03T07:16:02.542+0000] {warnings.py:110} WARNING - /home/***/.local/lib/python3.12/site-packages/***/task/task_runner/standard_task_runner.py:61: DeprecationWarning: This process (pid=907) is multi-threaded, use of fork() may lead to deadlocks in the child.
  pid = os.fork()

[2024-12-03T07:16:02.546+0000] {standard_task_runner.py:63} INFO - Started process 909 to run task
[2024-12-03T07:16:02.546+0000] {standard_task_runner.py:90} INFO - Running: ['***', 'tasks', 'run', 'job_listings_etl_v2', 'extract_csv', 'scheduled__2024-12-02T00:00:00+00:00', '--job-id', '39', '--raw', '--subdir', 'DAGS_FOLDER/ETL_FINAL_PROJECT (1).py', '--cfg-path', '/tmp/tmpmir8xzb6']
[2024-12-03T07:16:02.548+0000] {standard_task_runner.py:91} INFO - Job 39: Subtask extract_csv
[2024-12-03T07:16:02.602+0000] {task_command.py:426} INFO - Running <TaskInstance: job_listings_etl_v2.extract_csv scheduled__2024-12-02T00:00:00+00:00 [running]> on host 2adeb2e19af7
[2024-12-03T07:16:02.691+0000] {taskinstance.py:2648} INFO - Exporting env vars: AIRFLOW_CTX_DAG_OWNER='***' AIRFLOW_CTX_DAG_ID='job_listings_etl_v2' AIRFLOW_CTX_TASK_ID='extract_csv' AIRFLOW_CTX_EXECUTION_DATE='2024-12-02T00:00:00+00:00' AIRFLOW_CTX_TRY_NUMBER='4' AIRFLOW_CTX_DAG_RUN_ID='scheduled__2024-12-02T00:00:00+00:00'
[2024-12-03T07:16:02.694+0000] {taskinstance.py:430} INFO - ::endgroup::
[2024-12-03T07:16:02.717+0000] {base.py:84} INFO - Using connection ID 'snowflake_conn' for task execution.
[2024-12-03T07:16:02.719+0000] {connection.py:399} INFO - Snowflake Connector for Python Version: 3.10.0, Python Version: 3.12.3, Platform: Linux-5.10.25-linuxkit-aarch64-with-glibc2.36
[2024-12-03T07:16:02.720+0000] {connection.py:1239} INFO - This connection is in OCSP Fail Open Mode. TLS Certificates would be checked for validity and revocation status. Any other Certificate Revocation related exceptions or OCSP Responder failures would be disregarded in favor of connectivity.
[2024-12-03T07:16:04.398+0000] {ETL_FINAL_PROJECT (1).py:150} ERROR - Failed to extract data from Snowflake: 002003 (42S02): 01b8c734-0000-1b08-0000-370d0004247a: SQL compilation error:
Object 'DEV.RAW_DATA.DEMO_HISTORICAL' does not exist or not authorized.
[2024-12-03T07:16:04.403+0000] {taskinstance.py:441} INFO - ::group::Post task execution logs
[2024-12-03T07:16:04.428+0000] {taskinstance.py:2905} ERROR - Task failed with exception
Traceback (most recent call last):
  File "/opt/airflow/dags/ETL_FINAL_PROJECT (1).py", line 142, in extract_csv
    cur.execute(query)
  File "/home/airflow/.local/lib/python3.12/site-packages/snowflake/connector/cursor.py", line 1080, in execute
    Error.errorhandler_wrapper(self.connection, self, error_class, errvalue)
  File "/home/airflow/.local/lib/python3.12/site-packages/snowflake/connector/errors.py", line 290, in errorhandler_wrapper
    handed_over = Error.hand_to_other_handler(
                  ^^^^^^^^^^^^^^^^^^^^^^^^^^^^
  File "/home/airflow/.local/lib/python3.12/site-packages/snowflake/connector/errors.py", line 345, in hand_to_other_handler
    cursor.errorhandler(connection, cursor, error_class, error_value)
  File "/home/airflow/.local/lib/python3.12/site-packages/snowflake/connector/errors.py", line 221, in default_errorhandler
    raise error_class(
snowflake.connector.errors.ProgrammingError: 002003 (42S02): 01b8c734-0000-1b08-0000-370d0004247a: SQL compilation error:
Object 'DEV.RAW_DATA.DEMO_HISTORICAL' does not exist or not authorized.

During handling of the above exception, another exception occurred:

Traceback (most recent call last):
  File "/home/airflow/.local/lib/python3.12/site-packages/airflow/models/taskinstance.py", line 465, in _execute_task
    result = _execute_callable(context=context, **execute_callable_kwargs)
             ^^^^^^^^^^^^^^^^^^^^^^^^^^^^^^^^^^^^^^^^^^^^^^^^^^^^^^^^^^^^^
  File "/home/airflow/.local/lib/python3.12/site-packages/airflow/models/taskinstance.py", line 432, in _execute_callable
    return execute_callable(context=context, **execute_callable_kwargs)
           ^^^^^^^^^^^^^^^^^^^^^^^^^^^^^^^^^^^^^^^^^^^^^^^^^^^^^^^^^^^^
  File "/home/airflow/.local/lib/python3.12/site-packages/airflow/models/baseoperator.py", line 400, in wrapper
    return func(self, *args, **kwargs)
           ^^^^^^^^^^^^^^^^^^^^^^^^^^^
  File "/home/airflow/.local/lib/python3.12/site-packages/airflow/decorators/base.py", line 265, in execute
    return_value = super().execute(context)
                   ^^^^^^^^^^^^^^^^^^^^^^^^
  File "/home/airflow/.local/lib/python3.12/site-packages/airflow/models/baseoperator.py", line 400, in wrapper
    return func(self, *args, **kwargs)
           ^^^^^^^^^^^^^^^^^^^^^^^^^^^
  File "/home/airflow/.local/lib/python3.12/site-packages/airflow/operators/python.py", line 235, in execute
    return_value = self.execute_callable()
                   ^^^^^^^^^^^^^^^^^^^^^^^
  File "/home/airflow/.local/lib/python3.12/site-packages/airflow/operators/python.py", line 252, in execute_callable
    return self.python_callable(*self.op_args, **self.op_kwargs)
           ^^^^^^^^^^^^^^^^^^^^^^^^^^^^^^^^^^^^^^^^^^^^^^^^^^^^^
  File "/opt/airflow/dags/ETL_FINAL_PROJECT (1).py", line 151, in extract_csv
    raise AirflowException(f"Failed to extract data from Snowflake: {e}")
airflow.exceptions.AirflowException: Failed to extract data from Snowflake: 002003 (42S02): 01b8c734-0000-1b08-0000-370d0004247a: SQL compilation error:
Object 'DEV.RAW_DATA.DEMO_HISTORICAL' does not exist or not authorized.
[2024-12-03T07:16:04.437+0000] {taskinstance.py:1206} INFO - Marking task as FAILED. dag_id=job_listings_etl_v2, task_id=extract_csv, run_id=scheduled__2024-12-02T00:00:00+00:00, execution_date=20241202T000000, start_date=20241203T071602, end_date=20241203T071604
[2024-12-03T07:16:04.458+0000] {standard_task_runner.py:110} ERROR - Failed to execute job 39 for task extract_csv (Failed to extract data from Snowflake: 002003 (42S02): 01b8c734-0000-1b08-0000-370d0004247a: SQL compilation error:
Object 'DEV.RAW_DATA.DEMO_HISTORICAL' does not exist or not authorized.; 909)
[2024-12-03T07:16:04.519+0000] {local_task_job_runner.py:240} INFO - Task exited with return code 1
[2024-12-03T07:16:04.563+0000] {taskinstance.py:3498} INFO - 0 downstream tasks scheduled from follow-on schedule check
[2024-12-03T07:16:04.570+0000] {local_task_job_runner.py:222} INFO - ::endgroup::
