[2024-12-05T23:04:25.792+0000] {local_task_job_runner.py:120} INFO - ::group::Pre task execution logs
[2024-12-05T23:04:25.809+0000] {taskinstance.py:2076} INFO - Dependencies all met for dep_context=non-requeueable deps ti=<TaskInstance: job_listings_etl_v2.load_csv manual__2024-12-05T22:51:16.859148+00:00 [queued]>
[2024-12-05T23:04:25.816+0000] {taskinstance.py:2076} INFO - Dependencies all met for dep_context=requeueable deps ti=<TaskInstance: job_listings_etl_v2.load_csv manual__2024-12-05T22:51:16.859148+00:00 [queued]>
[2024-12-05T23:04:25.817+0000] {taskinstance.py:2306} INFO - Starting attempt 3 of 4
[2024-12-05T23:04:25.826+0000] {taskinstance.py:2330} INFO - Executing <Task(_PythonDecoratedOperator): load_csv> on 2024-12-05 22:51:16.859148+00:00
[2024-12-05T23:04:25.840+0000] {warnings.py:110} WARNING - /home/***/.local/lib/python3.12/site-packages/***/task/task_runner/standard_task_runner.py:61: DeprecationWarning: This process (pid=654) is multi-threaded, use of fork() may lead to deadlocks in the child.
  pid = os.fork()

[2024-12-05T23:04:25.845+0000] {standard_task_runner.py:63} INFO - Started process 656 to run task
[2024-12-05T23:04:25.844+0000] {standard_task_runner.py:90} INFO - Running: ['***', 'tasks', 'run', 'job_listings_etl_v2', 'load_csv', 'manual__2024-12-05T22:51:16.859148+00:00', '--job-id', '26', '--raw', '--subdir', 'DAGS_FOLDER/ETL_FINAL_PROJECT (1).py', '--cfg-path', '/tmp/tmpf8t1qxxn']
[2024-12-05T23:04:25.847+0000] {standard_task_runner.py:91} INFO - Job 26: Subtask load_csv
[2024-12-05T23:04:25.921+0000] {task_command.py:426} INFO - Running <TaskInstance: job_listings_etl_v2.load_csv manual__2024-12-05T22:51:16.859148+00:00 [running]> on host 1ed1f547130e
[2024-12-05T23:04:26.020+0000] {taskinstance.py:2648} INFO - Exporting env vars: AIRFLOW_CTX_DAG_OWNER='***' AIRFLOW_CTX_DAG_ID='job_listings_etl_v2' AIRFLOW_CTX_TASK_ID='load_csv' AIRFLOW_CTX_EXECUTION_DATE='2024-12-05T22:51:16.859148+00:00' AIRFLOW_CTX_TRY_NUMBER='3' AIRFLOW_CTX_DAG_RUN_ID='manual__2024-12-05T22:51:16.859148+00:00'
[2024-12-05T23:04:26.023+0000] {taskinstance.py:430} INFO - ::endgroup::
[2024-12-05T23:04:26.027+0000] {taskinstance.py:441} INFO - ::group::Post task execution logs
[2024-12-05T23:04:26.028+0000] {taskinstance.py:2905} ERROR - Task failed with exception
Traceback (most recent call last):
  File "/home/airflow/.local/lib/python3.12/site-packages/airflow/models/taskinstance.py", line 465, in _execute_task
    result = _execute_callable(context=context, **execute_callable_kwargs)
             ^^^^^^^^^^^^^^^^^^^^^^^^^^^^^^^^^^^^^^^^^^^^^^^^^^^^^^^^^^^^^
  File "/home/airflow/.local/lib/python3.12/site-packages/airflow/models/taskinstance.py", line 432, in _execute_callable
    return execute_callable(context=context, **execute_callable_kwargs)
           ^^^^^^^^^^^^^^^^^^^^^^^^^^^^^^^^^^^^^^^^^^^^^^^^^^^^^^^^^^^^
  File "/home/airflow/.local/lib/python3.12/site-packages/airflow/models/baseoperator.py", line 400, in wrapper
    return func(self, *args, **kwargs)
           ^^^^^^^^^^^^^^^^^^^^^^^^^^^
  File "/home/airflow/.local/lib/python3.12/site-packages/airflow/decorators/base.py", line 265, in execute
    return_value = super().execute(context)
                   ^^^^^^^^^^^^^^^^^^^^^^^^
  File "/home/airflow/.local/lib/python3.12/site-packages/airflow/models/baseoperator.py", line 400, in wrapper
    return func(self, *args, **kwargs)
           ^^^^^^^^^^^^^^^^^^^^^^^^^^^
  File "/home/airflow/.local/lib/python3.12/site-packages/airflow/operators/python.py", line 235, in execute
    return_value = self.execute_callable()
                   ^^^^^^^^^^^^^^^^^^^^^^^
  File "/home/airflow/.local/lib/python3.12/site-packages/airflow/operators/python.py", line 252, in execute_callable
    return self.python_callable(*self.op_args, **self.op_kwargs)
           ^^^^^^^^^^^^^^^^^^^^^^^^^^^^^^^^^^^^^^^^^^^^^^^^^^^^^
  File "/opt/airflow/dags/ETL_FINAL_PROJECT (1).py", line 32, in load_csv
    raw_data = pd.read_csv('path_to_your_file.csv')
               ^^^^^^^^^^^^^^^^^^^^^^^^^^^^^^^^^^^^
  File "/home/airflow/.local/lib/python3.12/site-packages/pandas/io/parsers/readers.py", line 948, in read_csv
    return _read(filepath_or_buffer, kwds)
           ^^^^^^^^^^^^^^^^^^^^^^^^^^^^^^^
  File "/home/airflow/.local/lib/python3.12/site-packages/pandas/io/parsers/readers.py", line 611, in _read
    parser = TextFileReader(filepath_or_buffer, **kwds)
             ^^^^^^^^^^^^^^^^^^^^^^^^^^^^^^^^^^^^^^^^^^
  File "/home/airflow/.local/lib/python3.12/site-packages/pandas/io/parsers/readers.py", line 1448, in __init__
    self._engine = self._make_engine(f, self.engine)
                   ^^^^^^^^^^^^^^^^^^^^^^^^^^^^^^^^^
  File "/home/airflow/.local/lib/python3.12/site-packages/pandas/io/parsers/readers.py", line 1705, in _make_engine
    self.handles = get_handle(
                   ^^^^^^^^^^^
  File "/home/airflow/.local/lib/python3.12/site-packages/pandas/io/common.py", line 863, in get_handle
    handle = open(
             ^^^^^
FileNotFoundError: [Errno 2] No such file or directory: 'path_to_your_file.csv'
[2024-12-05T23:04:26.040+0000] {taskinstance.py:1206} INFO - Marking task as FAILED. dag_id=job_listings_etl_v2, task_id=load_csv, run_id=manual__2024-12-05T22:51:16.859148+00:00, execution_date=20241205T225116, start_date=20241205T230425, end_date=20241205T230426
[2024-12-05T23:04:26.055+0000] {standard_task_runner.py:110} ERROR - Failed to execute job 26 for task load_csv ([Errno 2] No such file or directory: 'path_to_your_file.csv'; 656)
[2024-12-05T23:04:26.102+0000] {local_task_job_runner.py:240} INFO - Task exited with return code 1
[2024-12-05T23:04:26.163+0000] {taskinstance.py:3498} INFO - 0 downstream tasks scheduled from follow-on schedule check
[2024-12-05T23:04:26.167+0000] {local_task_job_runner.py:222} INFO - ::endgroup::
