[2024-12-03T06:50:26.658+0000] {local_task_job_runner.py:120} INFO - ::group::Pre task execution logs
[2024-12-03T06:50:27.006+0000] {taskinstance.py:2076} INFO - Dependencies all met for dep_context=non-requeueable deps ti=<TaskInstance: job_listings_etl_v2.load_api scheduled__2024-12-02T00:00:00+00:00 [queued]>
[2024-12-03T06:50:27.094+0000] {taskinstance.py:2076} INFO - Dependencies all met for dep_context=requeueable deps ti=<TaskInstance: job_listings_etl_v2.load_api scheduled__2024-12-02T00:00:00+00:00 [queued]>
[2024-12-03T06:50:27.099+0000] {taskinstance.py:2306} INFO - Starting attempt 2 of 4
[2024-12-03T06:50:27.180+0000] {taskinstance.py:2330} INFO - Executing <Task(_PythonDecoratedOperator): load_api> on 2024-12-02 00:00:00+00:00
[2024-12-03T06:50:27.244+0000] {warnings.py:110} WARNING - /home/***/.local/lib/python3.12/site-packages/***/task/task_runner/standard_task_runner.py:61: DeprecationWarning: This process (pid=462) is multi-threaded, use of fork() may lead to deadlocks in the child.
  pid = os.fork()

[2024-12-03T06:50:27.254+0000] {standard_task_runner.py:63} INFO - Started process 471 to run task
[2024-12-03T06:50:27.256+0000] {standard_task_runner.py:90} INFO - Running: ['***', 'tasks', 'run', 'job_listings_etl_v2', 'load_api', 'scheduled__2024-12-02T00:00:00+00:00', '--job-id', '21', '--raw', '--subdir', 'DAGS_FOLDER/ETL_FINAL_PROJECT (1).py', '--cfg-path', '/tmp/tmp4jyttkzw']
[2024-12-03T06:50:27.264+0000] {standard_task_runner.py:91} INFO - Job 21: Subtask load_api
[2024-12-03T06:50:27.441+0000] {task_command.py:426} INFO - Running <TaskInstance: job_listings_etl_v2.load_api scheduled__2024-12-02T00:00:00+00:00 [running]> on host 2adeb2e19af7
[2024-12-03T06:50:27.653+0000] {taskinstance.py:2648} INFO - Exporting env vars: AIRFLOW_CTX_DAG_OWNER='***' AIRFLOW_CTX_DAG_ID='job_listings_etl_v2' AIRFLOW_CTX_TASK_ID='load_api' AIRFLOW_CTX_EXECUTION_DATE='2024-12-02T00:00:00+00:00' AIRFLOW_CTX_TRY_NUMBER='2' AIRFLOW_CTX_DAG_RUN_ID='scheduled__2024-12-02T00:00:00+00:00'
[2024-12-03T06:50:27.659+0000] {taskinstance.py:430} INFO - ::endgroup::
[2024-12-03T06:50:27.748+0000] {base.py:84} INFO - Using connection ID 'snowflake_conn' for task execution.
[2024-12-03T06:50:27.770+0000] {connection.py:399} INFO - Snowflake Connector for Python Version: 3.10.0, Python Version: 3.12.3, Platform: Linux-5.10.25-linuxkit-aarch64-with-glibc2.36
[2024-12-03T06:50:27.781+0000] {connection.py:1239} INFO - This connection is in OCSP Fail Open Mode. TLS Certificates would be checked for validity and revocation status. Any other Certificate Revocation related exceptions or OCSP Responder failures would be disregarded in favor of connectivity.
[2024-12-03T06:50:29.934+0000] {cursor.py:1149} INFO - Number of results in first chunk: 1
[2024-12-03T06:50:30.243+0000] {ETL_FINAL_PROJECT (1).py:131} ERROR - Error loading data into Snowflake: 000904 (42000): 01b8c71a-0000-1b08-0000-370d0004225a: SQL compilation error: error line 24 at position 58
invalid identifier 'DESCRIPTION'
[2024-12-03T06:50:30.259+0000] {taskinstance.py:441} INFO - ::group::Post task execution logs
[2024-12-03T06:50:30.346+0000] {taskinstance.py:2905} ERROR - Task failed with exception
Traceback (most recent call last):
  File "/opt/airflow/dags/ETL_FINAL_PROJECT (1).py", line 124, in load_api
    cur.executemany(insert_query, [
  File "/home/airflow/.local/lib/python3.12/site-packages/snowflake/connector/cursor.py", line 1437, in executemany
    self.execute(command, params=param, _do_reset=False, **kwargs)
  File "/home/airflow/.local/lib/python3.12/site-packages/snowflake/connector/cursor.py", line 1080, in execute
    Error.errorhandler_wrapper(self.connection, self, error_class, errvalue)
  File "/home/airflow/.local/lib/python3.12/site-packages/snowflake/connector/errors.py", line 290, in errorhandler_wrapper
    handed_over = Error.hand_to_other_handler(
                  ^^^^^^^^^^^^^^^^^^^^^^^^^^^^
  File "/home/airflow/.local/lib/python3.12/site-packages/snowflake/connector/errors.py", line 345, in hand_to_other_handler
    cursor.errorhandler(connection, cursor, error_class, error_value)
  File "/home/airflow/.local/lib/python3.12/site-packages/snowflake/connector/errors.py", line 221, in default_errorhandler
    raise error_class(
snowflake.connector.errors.ProgrammingError: 000904 (42000): 01b8c71a-0000-1b08-0000-370d0004225a: SQL compilation error: error line 24 at position 58
invalid identifier 'DESCRIPTION'

During handling of the above exception, another exception occurred:

Traceback (most recent call last):
  File "/home/airflow/.local/lib/python3.12/site-packages/airflow/models/taskinstance.py", line 465, in _execute_task
    result = _execute_callable(context=context, **execute_callable_kwargs)
             ^^^^^^^^^^^^^^^^^^^^^^^^^^^^^^^^^^^^^^^^^^^^^^^^^^^^^^^^^^^^^
  File "/home/airflow/.local/lib/python3.12/site-packages/airflow/models/taskinstance.py", line 432, in _execute_callable
    return execute_callable(context=context, **execute_callable_kwargs)
           ^^^^^^^^^^^^^^^^^^^^^^^^^^^^^^^^^^^^^^^^^^^^^^^^^^^^^^^^^^^^
  File "/home/airflow/.local/lib/python3.12/site-packages/airflow/models/baseoperator.py", line 400, in wrapper
    return func(self, *args, **kwargs)
           ^^^^^^^^^^^^^^^^^^^^^^^^^^^
  File "/home/airflow/.local/lib/python3.12/site-packages/airflow/decorators/base.py", line 265, in execute
    return_value = super().execute(context)
                   ^^^^^^^^^^^^^^^^^^^^^^^^
  File "/home/airflow/.local/lib/python3.12/site-packages/airflow/models/baseoperator.py", line 400, in wrapper
    return func(self, *args, **kwargs)
           ^^^^^^^^^^^^^^^^^^^^^^^^^^^
  File "/home/airflow/.local/lib/python3.12/site-packages/airflow/operators/python.py", line 235, in execute
    return_value = self.execute_callable()
                   ^^^^^^^^^^^^^^^^^^^^^^^
  File "/home/airflow/.local/lib/python3.12/site-packages/airflow/operators/python.py", line 252, in execute_callable
    return self.python_callable(*self.op_args, **self.op_kwargs)
           ^^^^^^^^^^^^^^^^^^^^^^^^^^^^^^^^^^^^^^^^^^^^^^^^^^^^^
  File "/opt/airflow/dags/ETL_FINAL_PROJECT (1).py", line 132, in load_api
    raise AirflowException(f"Failed to load data into Snowflake: {str(e)}")
airflow.exceptions.AirflowException: Failed to load data into Snowflake: 000904 (42000): 01b8c71a-0000-1b08-0000-370d0004225a: SQL compilation error: error line 24 at position 58
invalid identifier 'DESCRIPTION'
[2024-12-03T06:50:30.362+0000] {taskinstance.py:1206} INFO - Marking task as UP_FOR_RETRY. dag_id=job_listings_etl_v2, task_id=load_api, run_id=scheduled__2024-12-02T00:00:00+00:00, execution_date=20241202T000000, start_date=20241203T065027, end_date=20241203T065030
[2024-12-03T06:50:30.403+0000] {standard_task_runner.py:110} ERROR - Failed to execute job 21 for task load_api (Failed to load data into Snowflake: 000904 (42000): 01b8c71a-0000-1b08-0000-370d0004225a: SQL compilation error: error line 24 at position 58
invalid identifier 'DESCRIPTION'; 471)
[2024-12-03T06:50:30.546+0000] {local_task_job_runner.py:240} INFO - Task exited with return code 1
[2024-12-03T06:50:30.677+0000] {taskinstance.py:3498} INFO - 0 downstream tasks scheduled from follow-on schedule check
[2024-12-03T06:50:30.680+0000] {local_task_job_runner.py:222} INFO - ::endgroup::
