[2024-12-04T19:51:22.719+0000] {task_context_logger.py:104} WARNING - Marking task instance <TaskInstance: BuildELT_dbt.dbt_run scheduled__2024-12-03T06:00:00+00:00 [queued]> stuck in queued as failed. If the task instance has available retries, it will be retried.
[2024-12-04T19:51:23.002+0000] {task_context_logger.py:104} ERROR - Executor reports task instance <TaskInstance: BuildELT_dbt.dbt_run scheduled__2024-12-03T06:00:00+00:00 [queued]> finished (failed) although the task says it's queued. (Info: None) Was the task killed externally?
