[2024-12-03T19:02:00.663+0000] {local_task_job_runner.py:120} INFO - ::group::Pre task execution logs
[2024-12-03T19:02:00.678+0000] {taskinstance.py:2076} INFO - Dependencies all met for dep_context=non-requeueable deps ti=<TaskInstance: BuildELT_dbt.dbt_run manual__2024-12-03T19:01:56.674785+00:00 [queued]>
[2024-12-03T19:02:00.684+0000] {taskinstance.py:2076} INFO - Dependencies all met for dep_context=requeueable deps ti=<TaskInstance: BuildELT_dbt.dbt_run manual__2024-12-03T19:01:56.674785+00:00 [queued]>
[2024-12-03T19:02:00.685+0000] {taskinstance.py:2306} INFO - Starting attempt 1 of 1
[2024-12-03T19:02:00.692+0000] {taskinstance.py:2330} INFO - Executing <Task(BashOperator): dbt_run> on 2024-12-03 19:01:56.674785+00:00
[2024-12-03T19:02:00.720+0000] {warnings.py:110} WARNING - /home/***/.local/lib/python3.12/site-packages/***/task/task_runner/standard_task_runner.py:61: DeprecationWarning: This process (pid=2609) is multi-threaded, use of fork() may lead to deadlocks in the child.
  pid = os.fork()

[2024-12-03T19:02:00.723+0000] {standard_task_runner.py:63} INFO - Started process 2611 to run task
[2024-12-03T19:02:00.722+0000] {standard_task_runner.py:90} INFO - Running: ['***', 'tasks', 'run', 'BuildELT_dbt', 'dbt_run', 'manual__2024-12-03T19:01:56.674785+00:00', '--job-id', '63', '--raw', '--subdir', 'DAGS_FOLDER/build_elt_with_dbt.py', '--cfg-path', '/tmp/tmpj0t8mqyt']
[2024-12-03T19:02:00.725+0000] {standard_task_runner.py:91} INFO - Job 63: Subtask dbt_run
[2024-12-03T19:02:00.763+0000] {task_command.py:426} INFO - Running <TaskInstance: BuildELT_dbt.dbt_run manual__2024-12-03T19:01:56.674785+00:00 [running]> on host 2adeb2e19af7
[2024-12-03T19:02:00.844+0000] {taskinstance.py:2648} INFO - Exporting env vars: AIRFLOW_CTX_DAG_OWNER='***' AIRFLOW_CTX_DAG_ID='BuildELT_dbt' AIRFLOW_CTX_TASK_ID='dbt_run' AIRFLOW_CTX_EXECUTION_DATE='2024-12-03T19:01:56.674785+00:00' AIRFLOW_CTX_TRY_NUMBER='1' AIRFLOW_CTX_DAG_RUN_ID='manual__2024-12-03T19:01:56.674785+00:00'
[2024-12-03T19:02:00.848+0000] {taskinstance.py:430} INFO - ::endgroup::
[2024-12-03T19:02:00.853+0000] {subprocess.py:63} INFO - Tmp dir root location: /tmp
[2024-12-03T19:02:00.855+0000] {subprocess.py:75} INFO - Running command: ['/usr/bin/bash', '-c', '/home/***/.local/bin/dbt run --profiles-dir /opt/***/final_dbt --project-dir /opt/***/final_dbt']
[2024-12-03T19:02:00.872+0000] {subprocess.py:86} INFO - Output:
[2024-12-03T19:02:03.804+0000] {subprocess.py:93} INFO - [0m19:02:03  Running with dbt=1.8.7
[2024-12-03T19:02:06.056+0000] {subprocess.py:93} INFO - [0m19:02:06  Registered adapter: snowflake=1.8.4
[2024-12-03T19:02:06.719+0000] {subprocess.py:93} INFO - [0m19:02:06  [[33mWARNING[0m]: Configuration paths exist in your dbt_project.yml file which do not apply to any resources.
[2024-12-03T19:02:06.723+0000] {subprocess.py:93} INFO - There are 1 unused configuration paths:
[2024-12-03T19:02:06.724+0000] {subprocess.py:93} INFO - - models.final_dbt.example
[2024-12-03T19:02:06.883+0000] {subprocess.py:93} INFO - [0m19:02:06  Found 1 snapshot, 3 models, 2 sources, 459 macros
[2024-12-03T19:02:06.888+0000] {subprocess.py:93} INFO - [0m19:02:06
[2024-12-03T19:02:12.719+0000] {subprocess.py:93} INFO - [0m19:02:12  Concurrency: 1 threads (target='dev')
[2024-12-03T19:02:12.728+0000] {subprocess.py:93} INFO - [0m19:02:12
[2024-12-03T19:02:12.751+0000] {subprocess.py:93} INFO - [0m19:02:12  1 of 3 START sql table model analytics.stg_job_listings ........................ [RUN]
[2024-12-03T19:02:15.664+0000] {subprocess.py:93} INFO - [0m19:02:15  1 of 3 OK created sql table model analytics.stg_job_listings ................... [[32mSUCCESS 1[0m in 2.91s]
[2024-12-03T19:02:15.671+0000] {subprocess.py:93} INFO - [0m19:02:15  2 of 3 START sql table model analytics.stg_job_listings_history ................ [RUN]
[2024-12-03T19:02:18.423+0000] {subprocess.py:93} INFO - [0m19:02:18  2 of 3 OK created sql table model analytics.stg_job_listings_history ........... [[32mSUCCESS 1[0m in 2.71s]
[2024-12-03T19:02:18.480+0000] {subprocess.py:93} INFO - [0m19:02:18  3 of 3 START sql table model analytics.job_salary_trends ....................... [RUN]
[2024-12-03T19:02:20.601+0000] {subprocess.py:93} INFO - [0m19:02:20  3 of 3 ERROR creating sql table model analytics.job_salary_trends .............. [[31mERROR[0m in 2.11s]
[2024-12-03T19:02:20.636+0000] {subprocess.py:93} INFO - [0m19:02:20
[2024-12-03T19:02:20.637+0000] {subprocess.py:93} INFO - [0m19:02:20  Finished running 3 table models in 0 hours 0 minutes and 13.74 seconds (13.74s).
[2024-12-03T19:02:20.982+0000] {subprocess.py:93} INFO - [0m19:02:20
[2024-12-03T19:02:20.986+0000] {subprocess.py:93} INFO - [0m19:02:20  [31mCompleted with 1 error and 0 warnings:[0m
[2024-12-03T19:02:20.989+0000] {subprocess.py:93} INFO - [0m19:02:20
[2024-12-03T19:02:20.992+0000] {subprocess.py:93} INFO - [0m19:02:20    Database Error in model job_salary_trends (models/output/job_salary_trends.sql)
[2024-12-03T19:02:20.993+0000] {subprocess.py:93} INFO -   000904 (42000): SQL compilation error: error line 10 at position 28
[2024-12-03T19:02:20.994+0000] {subprocess.py:93} INFO -   invalid identifier 'CREATED_AT'
[2024-12-03T19:02:21.000+0000] {subprocess.py:93} INFO -   compiled code at target/run/final_dbt/models/output/job_salary_trends.sql
[2024-12-03T19:02:21.005+0000] {subprocess.py:93} INFO - [0m19:02:21
[2024-12-03T19:02:21.010+0000] {subprocess.py:93} INFO - [0m19:02:21  Done. PASS=2 WARN=0 ERROR=1 SKIP=0 TOTAL=3
[2024-12-03T19:02:23.763+0000] {subprocess.py:97} INFO - Command exited with return code 1
[2024-12-03T19:02:23.811+0000] {taskinstance.py:441} INFO - ::group::Post task execution logs
[2024-12-03T19:02:23.933+0000] {taskinstance.py:2905} ERROR - Task failed with exception
Traceback (most recent call last):
  File "/home/airflow/.local/lib/python3.12/site-packages/airflow/models/taskinstance.py", line 465, in _execute_task
    result = _execute_callable(context=context, **execute_callable_kwargs)
             ^^^^^^^^^^^^^^^^^^^^^^^^^^^^^^^^^^^^^^^^^^^^^^^^^^^^^^^^^^^^^
  File "/home/airflow/.local/lib/python3.12/site-packages/airflow/models/taskinstance.py", line 432, in _execute_callable
    return execute_callable(context=context, **execute_callable_kwargs)
           ^^^^^^^^^^^^^^^^^^^^^^^^^^^^^^^^^^^^^^^^^^^^^^^^^^^^^^^^^^^^
  File "/home/airflow/.local/lib/python3.12/site-packages/airflow/models/baseoperator.py", line 400, in wrapper
    return func(self, *args, **kwargs)
           ^^^^^^^^^^^^^^^^^^^^^^^^^^^
  File "/home/airflow/.local/lib/python3.12/site-packages/airflow/operators/bash.py", line 243, in execute
    raise AirflowException(
airflow.exceptions.AirflowException: Bash command failed. The command returned a non-zero exit code 1.
[2024-12-03T19:02:24.013+0000] {taskinstance.py:1206} INFO - Marking task as FAILED. dag_id=BuildELT_dbt, task_id=dbt_run, run_id=manual__2024-12-03T19:01:56.674785+00:00, execution_date=20241203T190156, start_date=20241203T190200, end_date=20241203T190223
[2024-12-03T19:02:24.110+0000] {standard_task_runner.py:110} ERROR - Failed to execute job 63 for task dbt_run (Bash command failed. The command returned a non-zero exit code 1.; 2611)
[2024-12-03T19:02:24.213+0000] {local_task_job_runner.py:240} INFO - Task exited with return code 1
[2024-12-03T19:02:24.332+0000] {taskinstance.py:3498} INFO - 0 downstream tasks scheduled from follow-on schedule check
[2024-12-03T19:02:24.346+0000] {local_task_job_runner.py:222} INFO - ::endgroup::
