[2024-12-05T23:16:12.346+0000] {local_task_job_runner.py:120} INFO - ::group::Pre task execution logs
[2024-12-05T23:16:12.455+0000] {taskinstance.py:2076} INFO - Dependencies all met for dep_context=non-requeueable deps ti=<TaskInstance: job_listings_etl_v2.transform_csv manual__2024-12-05T23:15:58.336631+00:00 [queued]>
[2024-12-05T23:16:12.476+0000] {taskinstance.py:2076} INFO - Dependencies all met for dep_context=requeueable deps ti=<TaskInstance: job_listings_etl_v2.transform_csv manual__2024-12-05T23:15:58.336631+00:00 [queued]>
[2024-12-05T23:16:12.478+0000] {taskinstance.py:2306} INFO - Starting attempt 1 of 4
[2024-12-05T23:16:12.532+0000] {taskinstance.py:2330} INFO - Executing <Task(_PythonDecoratedOperator): transform_csv> on 2024-12-05 23:15:58.336631+00:00
[2024-12-05T23:16:12.597+0000] {warnings.py:110} WARNING - /home/***/.local/lib/python3.12/site-packages/***/task/task_runner/standard_task_runner.py:61: DeprecationWarning: This process (pid=871) is multi-threaded, use of fork() may lead to deadlocks in the child.
  pid = os.fork()

[2024-12-05T23:16:12.626+0000] {standard_task_runner.py:63} INFO - Started process 876 to run task
[2024-12-05T23:16:12.626+0000] {standard_task_runner.py:90} INFO - Running: ['***', 'tasks', 'run', 'job_listings_etl_v2', 'transform_csv', 'manual__2024-12-05T23:15:58.336631+00:00', '--job-id', '36', '--raw', '--subdir', 'DAGS_FOLDER/ETL_FINAL_PROJECT (1).py', '--cfg-path', '/tmp/tmpjroszw_k']
[2024-12-05T23:16:12.630+0000] {standard_task_runner.py:91} INFO - Job 36: Subtask transform_csv
[2024-12-05T23:16:12.869+0000] {task_command.py:426} INFO - Running <TaskInstance: job_listings_etl_v2.transform_csv manual__2024-12-05T23:15:58.336631+00:00 [running]> on host 1ed1f547130e
[2024-12-05T23:16:13.120+0000] {taskinstance.py:2648} INFO - Exporting env vars: AIRFLOW_CTX_DAG_OWNER='***' AIRFLOW_CTX_DAG_ID='job_listings_etl_v2' AIRFLOW_CTX_TASK_ID='transform_csv' AIRFLOW_CTX_EXECUTION_DATE='2024-12-05T23:15:58.336631+00:00' AIRFLOW_CTX_TRY_NUMBER='1' AIRFLOW_CTX_DAG_RUN_ID='manual__2024-12-05T23:15:58.336631+00:00'
[2024-12-05T23:16:13.133+0000] {taskinstance.py:430} INFO - ::endgroup::
[2024-12-05T23:16:13.137+0000] {ETL_FINAL_PROJECT (1).py:152} ERROR - No data received for transformation.
[2024-12-05T23:16:13.139+0000] {taskinstance.py:441} INFO - ::group::Post task execution logs
[2024-12-05T23:16:13.158+0000] {taskinstance.py:2905} ERROR - Task failed with exception
Traceback (most recent call last):
  File "/home/airflow/.local/lib/python3.12/site-packages/airflow/models/taskinstance.py", line 465, in _execute_task
    result = _execute_callable(context=context, **execute_callable_kwargs)
             ^^^^^^^^^^^^^^^^^^^^^^^^^^^^^^^^^^^^^^^^^^^^^^^^^^^^^^^^^^^^^
  File "/home/airflow/.local/lib/python3.12/site-packages/airflow/models/taskinstance.py", line 432, in _execute_callable
    return execute_callable(context=context, **execute_callable_kwargs)
           ^^^^^^^^^^^^^^^^^^^^^^^^^^^^^^^^^^^^^^^^^^^^^^^^^^^^^^^^^^^^
  File "/home/airflow/.local/lib/python3.12/site-packages/airflow/models/baseoperator.py", line 400, in wrapper
    return func(self, *args, **kwargs)
           ^^^^^^^^^^^^^^^^^^^^^^^^^^^
  File "/home/airflow/.local/lib/python3.12/site-packages/airflow/decorators/base.py", line 265, in execute
    return_value = super().execute(context)
                   ^^^^^^^^^^^^^^^^^^^^^^^^
  File "/home/airflow/.local/lib/python3.12/site-packages/airflow/models/baseoperator.py", line 400, in wrapper
    return func(self, *args, **kwargs)
           ^^^^^^^^^^^^^^^^^^^^^^^^^^^
  File "/home/airflow/.local/lib/python3.12/site-packages/airflow/operators/python.py", line 235, in execute
    return_value = self.execute_callable()
                   ^^^^^^^^^^^^^^^^^^^^^^^
  File "/home/airflow/.local/lib/python3.12/site-packages/airflow/operators/python.py", line 252, in execute_callable
    return self.python_callable(*self.op_args, **self.op_kwargs)
           ^^^^^^^^^^^^^^^^^^^^^^^^^^^^^^^^^^^^^^^^^^^^^^^^^^^^^
  File "/opt/airflow/dags/ETL_FINAL_PROJECT (1).py", line 153, in transform_csv
    raise AirflowException("No data received for transformation.")
airflow.exceptions.AirflowException: No data received for transformation.
[2024-12-05T23:16:13.170+0000] {taskinstance.py:1206} INFO - Marking task as UP_FOR_RETRY. dag_id=job_listings_etl_v2, task_id=transform_csv, run_id=manual__2024-12-05T23:15:58.336631+00:00, execution_date=20241205T231558, start_date=20241205T231612, end_date=20241205T231613
[2024-12-05T23:16:13.187+0000] {standard_task_runner.py:110} ERROR - Failed to execute job 36 for task transform_csv (No data received for transformation.; 876)
[2024-12-05T23:16:13.240+0000] {local_task_job_runner.py:240} INFO - Task exited with return code 1
[2024-12-05T23:16:13.295+0000] {taskinstance.py:3498} INFO - 0 downstream tasks scheduled from follow-on schedule check
[2024-12-05T23:16:13.299+0000] {local_task_job_runner.py:222} INFO - ::endgroup::
